<mujoco>

  <!-- Assets - textures and designs -->
  <asset> 
    <texture name="grid" type="2d" builtin="checker" width="512" height="512" rgb1=".1 .2 .3" rgb2=".2 .3 .4"/>
    <material name="grid" texture="grid" texrepeat="1 1" texuniform="true" reflectance=".2"/>

    <material name="wooden" rgba="0.6 0.4 0.2 1" shininess="0.6" specular="0.2" reflectance="0.5"/>

    <mesh name="chasis" scale=".01 .006 .0015"
      vertex=" 9   2   0
              -10  10  10
               9  -2   0
               10  3  -10
               10 -3  -10
              -8   10 -10
              -10 -10  10
              -8  -10 -10
              -5   0   20"/>
  </asset>

  <default>
    <default class="wheel">
      <geom type="cylinder" size=".03 .01" rgba=".5 .5 1 1"/>
    </default>
    <default class="decor">
      <site type="box" rgba=".5 1 .5 1"/>
    </default>
  </default>

  <worldbody>

    <!-- Ground plane & the walls -->
    <geom type="plane" size="3 3 .01" material="grid" friction="0.0"/>
    <geom type="box" size="3 0.05 0.1" pos="0 2.93 0.05" material="wooden"/> 
    <geom type="box" size="3 0.05 0.1" pos="0 -2.93 0.05" material="wooden"/> 
    <geom type="box" size="0.05 3 0.1" pos="2.93 0 0.05" material="wooden"/> 
    <geom type="box" size="0.05 3 0.1" pos="-2.93 0 0.05" material="wooden"/> 

    <!-- Greg Himself -->
    <body name="car" pos="0 0 .03" quat="0.7 0 0 0.7">
      <!-- Sensors for Greg (they don't for some reason) -->
      <!-- <sensor type="lidar" name="lidar1" pos="0 0 .1">
        <scan>
          <samples>100</samples>
          <fov>270</fov>
          <range>30</range>
        </scan>
        <ray>
          <noise>
            <type>gaussian</type>
            <mean>0</mean>
            <stddev>0.01</stddev>
          </noise>
        </ray>
      </sensor>
      <sensor type="camera" name="camera1" pos="0 0 .1">
        <camera name="main">
          <mode>targetbody</mode>
          <target>car</target>
          <up>0 0 1</up>
          <fovy>60</fovy>
          <clip>
            <near>0.1</near>
            <far>100</far>
          </clip>
        </camera>
      </sensor> -->

      <!-- The Rest of Greg -->

      <freejoint/>
      <light name="top light" pos="0 0 2" mode="trackcom" diffuse=".4 .4 .4"/>
      <geom name="chasis" type="mesh" mesh="chasis"/>
      <geom name="front wheel" pos=".08 0 -.015" type="sphere" size=".015" condim="1" priority="1" friction="2.0"/>
      <light name="front light" pos=".1 0 .02" dir="2 0 -1" diffuse="1 1 1"/>

      <body name="left wheel" pos="-.07 .06 0" zaxis="0 1 0">
        <joint name="left"/>
        <geom class="wheel" friction="2.0"/>
        <site class="decor" size=".006 .025 .012"/>
        <site class="decor" size=".025 .006 .012"/>
      </body>

      <body name="right wheel" pos="-.07 -.06 0" zaxis="0 1 0">
        <joint name="right"/>
        <geom class="wheel" friction="2.0"/>
        <site class="decor" size=".006 .025 .012"/>
        <site class="decor" size=".025 .006 .012"/>
      </body>

    </body>

    <!-- Greg's Goal -->
    <body name="goal" pos="1.0 1.0 0.32">
      <joint name="goal" type="hinge"/>
      <geom type="sphere" size="0.05" rgba="1 0 0 1" group="0" solref="0.001 1" solimp="0.01 0.99"/>
    </body>
    
  </worldbody>

  <!-- Tendons and Actuators for moving Greg -->
  <tendon>
    <fixed name="forward">
      <joint joint="left" coef=".5"/>
      <joint joint="right" coef=".5"/>
    </fixed>
    <fixed name="turn">
      <joint joint="left" coef="-.5"/>
      <joint joint="right" coef=".5"/>
    </fixed>
  </tendon>

  <actuator>
    <motor name="forward" tendon="forward" ctrlrange="-1 1"/>
    <motor name="turn" tendon="turn" ctrlrange="-1 1"/>
  </actuator>

 
</mujoco>
